Workbook

Sheet Питание
A1: Дневник питания и веса
A2: Вноси каждый день: вес утром (натощак, после туалета), калории, белок, жиры, углеводы, клетчатку, воду (л). Синие ячейки на жёлтом фоне — ввод, остальное считается само. Взвешивайся ежедневно, оценивай по среднему за 7 дней, а не по одному числу.
A3: 46294 | B3: 82.5 | C3: 2180 | D3: 165 | E3: 70 | F3: 225 | G3: 30 | H3: 2.8 | I3: ← пример строки (не считается)
A5: Сводка (последние 7 дней с записями) | C5: Ккал | D5: Белок, г | E5: Жиры, г | F5: Углеводы, г | G5: Клетчатка, г | H5: Вода, л
A6: Цель на день | C6: =TargetKcal -> 2200 | D6: =TargetProtein -> 165 | E6: =TargetFat -> 70 | F6: =TargetCarb -> 228 | G6: =TargetFiber -> 30 | H6: =TargetWater -> 2.8
A7: Факт: среднее за 7 дней | C7: =IF(LastFD=0,"",IFERROR(AVERAGEIFS(Питание!$C$14:$C$378,Питание!$A$14:$A$378,">"&LastFD-7,Питание!$A$14:$A$378,"<="&LastFD,Питание!$C$14:$C$378,">0"),"")) -> 2140 | D7: =IF(LastFD=0,"",IFERROR(AVERAGEIFS(Питание!$D$14:$D$378,Питание!$A$14:$A$378,">"&LastFD-7,Питание!$A$14:$A$378,"<="&LastFD,Питание!$D$14:$D$378,">0"),"")) -> 165 | E7: =IF(LastFD=0,"",IFERROR(AVERAGEIFS(Питание!$E$14:$E$378,Питание!$A$14:$A$378,">"&LastFD-7,Питание!$A$14:$A$378,"<="&LastFD,Питание!$E$14:$E$378,">0"),"")) -> 70 | F7: =IF(LastFD=0,"",IFERROR(AVERAGEIFS(Питание!$F$14:$F$378,Питание!$A$14:$A$378,">"&LastFD-7,Питание!$A$14:$A$378,"<="&LastFD,Питание!$F$14:$F$378,">0"),"")) -> 225 | G7: =IF(LastFD=0,"",IFERROR(AVERAGEIFS(Питание!$G$14:$G$378,Питание!$A$14:$A$378,">"&LastFD-7,Питание!$A$14:$A$378,"<="&LastFD,Питание!$G$14:$G$378,">0"),"")) -> 30 | H7: =IF(LastFD=0,"",IFERROR(AVERAGEIFS(Питание!$H$14:$H$378,Питание!$A$14:$A$378,">"&LastFD-7,Питание!$A$14:$A$378,"<="&LastFD,Питание!$H$14:$H$378,">0"),"")) -> 2.8
A8: Отклонение (факт − цель) | C8: =IF(C7="","",C7-C6) -> -60 | D8: =IF(D7="","",D7-D6) -> 0 | E8: =IF(E7="","",E7-E6) -> 0 | F8: =IF(F7="","",F7-F6) -> -3 | G8: =IF(G7="","",G7-G6) -> 0 | H8: =IF(H7="","",H7-H6) -> 0
A9: Отклонение, % | C9: =IF(C7="","",C7/C6-1) -> -0.027272727 | D9: =IF(D7="","",D7/D6-1) -> 0 | E9: =IF(E7="","",E7/E6-1) -> 0 | F9: =IF(F7="","",F7/F6-1) -> -0.013157895 | G9: =IF(G7="","",G7/G6-1) -> 0 | H9: =IF(H7="","",H7/H6-1) -> 0
A11: Вес | C11: Ср. вес 7 дн, кг | D11: Изм. за 7 дн, кг | E11: Темп, %/нед | F11: Δ к старту, кг | G11: Ср. вес 30 дн, кг | H11: Замеров веса
A12: По среднему за 7 дней | C12: =IF(LastWD=0,"",IFERROR(AVERAGEIFS(Питание!$B$14:$B$378,Питание!$A$14:$A$378,">"&LastWD-7,Питание!$A$14:$A$378,"<="&LastWD,Питание!$B$14:$B$378,">0"),"")) -> 82.34 | D12: =IF(C12="","",IFERROR(C12-AVERAGEIFS(Питание!$B$14:$B$378,Питание!$A$14:$A$378,">"&LastWD-14,Питание!$A$14:$A$378,"<="&LastWD-7,Питание!$B$14:$B$378,">0"),"")) | E12: =IF(D12="","",D12/C12) | F12: =IF(C12="","",C12-StartWeight) -> -0.16 | G12: =IF(LastWD=0,"",IFERROR(AVERAGEIFS(Питание!$B$14:$B$378,Питание!$A$14:$A$378,">"&LastWD-30,Питание!$A$14:$A$378,"<="&LastWD,Питание!$B$14:$B$378,">0"),"")) -> 82.34 | H12: =COUNT(Питание!$B$14:$B$378) -> 5
A13: Дата | B13: Вес утром, кг | C13: Ккал | D13: Белок, г | E13: Жиры, г | F13: Углеводы, г | G13: Клетчатка, г | H13: Вода, л | I13: Комментарий | J13: Откл. ккал | K13: Откл. белок, г | L13: Откл. жиры, г | M13: Откл. углеводы, г | N13: Расхожд. ккал и макро | O13: Ср. вес 7 дн, кг | P13: Ср. ккал 7 дн | Q13: Ср. белок 7 дн, г | R13: Изм. ср. веса за 7 дн, кг | S13: Темп, %/нед | T13: Δ к старту (ср.), кг
A14: =StartDate -> 46294 | B14: 82.5 | C14: 2180 | D14: 165 | E14: 70 | F14: 225 | G14: 30 | H14: 2.8 | J14: =IF(C14="","",C14-TargetKcal) -> -20 | K14: =IF(D14="","",D14-TargetProtein) -> 0 | L14: =IF(E14="","",E14-TargetFat) -> 0 | M14: =IF(F14="","",F14-TargetCarb) -> -3 | N14: =IF(COUNT(C14:F14)<4,"",ROUND(4*D14+9*E14+4*F14-C14,0)) -> 10 | O14: =IF(B14="","",IFERROR(AVERAGEIFS(Питание!$B$14:$B$378,Питание!$A$14:$A$378,">"&$A14-7,Питание!$A$14:$A$378,"<="&$A14,Питание!$B$14:$B$378,">0"),"")) -> 82.5 | P14: =IF(C14="","",IFERROR(AVERAGEIFS(Питание!$C$14:$C$378,Питание!$A$14:$A$378,">"&$A14-7,Питание!$A$14:$A$378,"<="&$A14,Питание!$C$14:$C$378,">0"),"")) -> 2180 | Q14: =IF(D14="","",IFERROR(AVERAGEIFS(Питание!$D$14:$D$378,Питание!$A$14:$A$378,">"&$A14-7,Питание!$A$14:$A$378,"<="&$A14,Питание!$D$14:$D$378,">0"),"")) -> 165 | R14: =IF(O14="","",IFERROR(O14-AVERAGEIFS(Питание!$B$14:$B$378,Питание!$A$14:$A$378,">"&$A14-14,Питание!$A$14:$A$378,"<="&$A14-7,Питание!$B$14:$B$378,">0"),"")) | S14: =IF(R14="","",R14/O14) | T14: =IF(O14="","",O14-StartWeight) -> 0
A15: =A14+1 -> 46295 | B15: 82.3 | C15: 2160 | D15: 165 | E15: 70 | F15: 225 | G15: 30 | H15: 2.8 | J15: =IF(C15="","",C15-TargetKcal) -> -40 | K15: =IF(D15="","",D15-TargetProtein) -> 0 | L15: =IF(E15="","",E15-TargetFat) -> 0 | M15: =IF(F15="","",F15-TargetCarb) -> -3 | N15: =IF(COUNT(C15:F15)<4,"",ROUND(4*D15+9*E15+4*F15-C15,0)) -> 30 | O15: =IF(B15="","",IFERROR(AVERAGEIFS(Питание!$B$14:$B$378,Питание!$A$14:$A$378,">"&$A15-7,Питание!$A$14:$A$378,"<="&$A15,Питание!$B$14:$B$378,">0"),"")) -> 82.4 | P15: =IF(C15="","",IFERROR(AVERAGEIFS(Питание!$C$14:$C$378,Питание!$A$14:$A$378,">"&$A15-7,Питание!$A$14:$A$378,"<="&$A15,Питание!$C$14:$C$378,">0"),"")) -> 2170 | Q15: =IF(D15="","",IFERROR(AVERAGEIFS(Питание!$D$14:$D$378,Питание!$A$14:$A$378,">"&$A15-7,Питание!$A$14:$A$378,"<="&$A15,Питание!$D$14:$D$378,">0"),"")) -> 165 | R15: =IF(O15="","",IFERROR(O15-AVERAGEIFS(Питание!$B$14:$B$378,Питание!$A$14:$A$378,">"&$A15-14,Питание!$A$14:$A$378,"<="&$A15-7,Питание!$B$14:$B$378,">0"),"")) | S15: =IF(R15="","",R15/O15) | T15: =IF(O15="","",O15-StartWeight) -> -0.1
A16: =A15+1 -> 46296 | B16: 82.6 | C16: 2140 | D16: 165 | E16: 70 | F16: 225 | G16: 30 | H16: 2.8 | J16: =IF(C16="","",C16-TargetKcal) -> -60 | K16: =IF(D16="","",D16-TargetProtein) -> 0 | L16: =IF(E16="","",E16-TargetFat) -> 0 | M16: =IF(F16="","",F16-TargetCarb) -> -3 | N16: =IF(COUNT(C16:F16)<4,"",ROUND(4*D16+9*E16+4*F16-C16,0)) -> 50 | O16: =IF(B16="","",IFERROR(AVERAGEIFS(Питание!$B$14:$B$378,Питание!$A$14:$A$378,">"&$A16-7,Питание!$A$14:$A$378,"<="&$A16,Питание!$B$14:$B$378,">0"),"")) -> 82.466667 | P16: =IF(C16="","",IFERROR(AVERAGEIFS(Питание!$C$14:$C$378,Питание!$A$14:$A$378,">"&$A16-7,Питание!$A$14:$A$378,"<="&$A16,Питание!$C$14:$C$378,">0"),"")) -> 2160 | Q16: =IF(D16="","",IFERROR(AVERAGEIFS(Питание!$D$14:$D$378,Питание!$A$14:$A$378,">"&$A16-7,Питание!$A$14:$A$378,"<="&$A16,Питание!$D$14:$D$378,">0"),"")) -> 165 | R16: =IF(O16="","",IFERROR(O16-AVERAGEIFS(Питание!$B$14:$B$378,Питание!$A$14:$A$378,">"&$A16-14,Питание!$A$14:$A$378,"<="&$A16-7,Питание!$B$14:$B$378,">0"),"")) | S16: =IF(R16="","",R16/O16) | T16: =IF(O16="","",O16-StartWeight) -> -0.033333333
A17: =A16+1 -> 46297 | B17: 82.2 | C17: 2120 | D17: 165 | E17: 70 | F17: 225 | G17: 30 | H17: 2.8 | J17: =IF(C17="","",C17-TargetKcal) -> -80 | K17: =IF(D17="","",D17-TargetProtein) -> 0 | L17: =IF(E17="","",E17-TargetFat) -> 0 | M17: =IF(F17="","",F17-TargetCarb) -> -3 | N17: =IF(COUNT(C17:F17)<4,"",ROUND(4*D17+9*E17+4*F17-C17,0)) -> 70 | O17: =IF(B17="","",IFERROR(AVERAGEIFS(Питание!$B$14:$B$378,Питание!$A$14:$A$378,">"&$A17-7,Питание!$A$14:$A$378,"<="&$A17,Питание!$B$14:$B$378,">0"),"")) -> 82.4 | P17: =IF(C17="","",IFERROR(AVERAGEIFS(Питание!$C$14:$C$378,Питание!$A$14:$A$378,">"&$A17-7,Питание!$A$14:$A$378,"<="&$A17,Питание!$C$14:$C$378,">0"),"")) -> 2150 | Q17: =IF(D17="","",IFERROR(AVERAGEIFS(Питание!$D$14:$D$378,Питание!$A$14:$A$378,">"&$A17-7,Питание!$A$14:$A$378,"<="&$A17,Питание!$D$14:$D$378,">0"),"")) -> 165 | R17: =IF(O17="","",IFERROR(O17-AVERAGEIFS(Питание!$B$14:$B$378,Питание!$A$14:$A$378,">"&$A17-14,Питание!$A$14:$A$378,"<="&$A17-7,Питание!$B$14:$B$378,">0"),"")) | S17: =IF(R17="","",R17/O17) | T17: =IF(O17="","",O17-StartWeight) -> -0.1
A18: =A17+1 -> 46298 | B18: 82.1 | C18: 2100 | D18: 165 | E18: 70 | F18: 225 | G18: 30 | H18: 2.8 | J18: =IF(C18="","",C18-TargetKcal) -> -100 | K18: =IF(D18="","",D18-TargetProtein) -> 0 | L18: =IF(E18="","",E18-TargetFat) -> 0 | M18: =IF(F18="","",F18-TargetCarb) -> -3 | N18: =IF(COUNT(C18:F18)<4,"",ROUND(4*D18+9*E18+4*F18-C18,0)) -> 90 | O18: =IF(B18="","",IFERROR(AVERAGEIFS(Питание!$B$14:$B$378,Питание!$A$14:$A$378,">"&$A18-7,Питание!$A$14:$A$378,"<="&$A18,Питание!$B$14:$B$378,">0"),"")) -> 82.34 | P18: =IF(C18="","",IFERROR(AVERAGEIFS(Питание!$C$14:$C$378,Питание!$A$14:$A$378,">"&$A18-7,Питание!$A$14:$A$378,"<="&$A18,Питание!$C$14:$C$378,">0"),"")) -> 2140 | Q18: =IF(D18="","",IFERROR(AVERAGEIFS(Питание!$D$14:$D$378,Питание!$A$14:$A$378,">"&$A18-7,Питание!$A$14:$A$378,"<="&$A18,Питание!$D$14:$D$378,">0"),"")) -> 165 | R18: =IF(O18="","",IFERROR(O18-AVERAGEIFS(Питание!$B$14:$B$378,Питание!$A$14:$A$378,">"&$A18-14,Питание!$A$14:$A$378,"<="&$A18-7,Питание!$B$14:$B$378,">0"),"")) | S18: =IF(R18="","",R18/O18) | T18: =IF(O18="","",O18-StartWeight) -> -0.16
A19: =A18+1 -> 46299 | B19: abc | J19: =IF(C19="","",C19-TargetKcal) | K19: =IF(D19="","",D19-TargetProtein) | L19: =IF(E19="","",E19-TargetFat) | M19: =IF(F19="","",F19-TargetCarb) | N19: =IF(COUNT(C19:F19)<4,"",ROUND(4*D19+9*E19+4*F19-C19,0)) | O19: =IF(B19="","",IFERROR(AVERAGEIFS(Питание!$B$14:$B$378,Питание!$A$14:$A$378,">"&$A19-7,Питание!$A$14:$A$378,"<="&$A19,Питание!$B$14:$B$378,">0"),"")) -> 82.34 | P19: =IF(C19="","",IFERROR(AVERAGEIFS(Питание!$C$14:$C$378,Питание!$A$14:$A$378,">"&$A19-7,Питание!$A$14:$A$378,"<="&$A19,Питание!$C$14:$C$378,">0"),"")) | Q19: =IF(D19="","",IFERROR(AVERAGEIFS(Питание!$D$14:$D$378,Питание!$A$14:$A$378,">"&$A19-7,Питание!$A$14:$A$378,"<="&$A19,Питание!$D$14:$D$378,">0"),"")) | R19: =IF(O19="","",IFERROR(O19-AVERAGEIFS(Питание!$B$14:$B$378,Питание!$A$14:$A$378,">"&$A19-14,Питание!$A$14:$A$378,"<="&$A19-7,Питание!$B$14:$B$378,">0"),"")) | S19: =IF(R19="","",R19/O19) | T19: =IF(O19="","",O19-StartWeight) -> -0.16
A20: =A19+1 -> 46300 | J20: =IF(C20="","",C20-TargetKcal) | K20: =IF(D20="","",D20-TargetProtein) | L20: =IF(E20="","",E20-TargetFat) | M20: =IF(F20="","",F20-TargetCarb) | N20: =IF(COUNT(C20:F20)<4,"",ROUND(4*D20+9*E20+4*F20-C20,0)) | O20: =IF(B20="","",IFERROR(AVERAGEIFS(Питание!$B$14:$B$378,Питание!$A$14:$A$378,">"&$A20-7,Питание!$A$14:$A$378,"<="&$A20,Питание!$B$14:$B$378,">0"),"")) | P20: =IF(C20="","",IFERROR(AVERAGEIFS(Питание!$C$14:$C$378,Питание!$A$14:$A$378,">"&$A20-7,Питание!$A$14:$A$378,"<="&$A20,Питание!$C$14:$C$378,">0"),"")) | Q20: =IF(D20="","",IFERROR(AVERAGEIFS(Питание!$D$14:$D$378,Питание!$A$14:$A$378,">"&$A20-7,Питание!$A$14:$A$378,"<="&$A20,Питание!$D$14:$D$378,">0"),"")) | R20: =IF(O20="","",IFERROR(O20-AVERAGEIFS(Питание!$B$14:$B$378,Питание!$A$14:$A$378,">"&$A20-14,Питание!$A$14:$A$378,"<="&$A20-7,Питание!$B$14:$B$378,">0"),"")) | S20: =IF(R20="","",R20/O20) | T20: =IF(O20="","",O20-StartWeight)
A21: =A20+1 -> 46301 | J21: =IF(C21="","",C21-TargetKcal) | K21: =IF(D21="","",D21-TargetProtein) | L21: =IF(E21="","",E21-TargetFat) | M21: =IF(F21="","",F21-TargetCarb) | N21: =IF(COUNT(C21:F21)<4,"",ROUND(4*D21+9*E21+4*F21-C21,0)) | O21: =IF(B21="","",IFERROR(AVERAGEIFS(Питание!$B$14:$B$378,Питание!$A$14:$A$378,">"&$A21-7,Питание!$A$14:$A$378,"<="&$A21,Питание!$B$14:$B$378,">0"),"")) | P21: =IF(C21="","",IFERROR(AVERAGEIFS(Питание!$C$14:$C$378,Питание!$A$14:$A$378,">"&$A21-7,Питание!$A$14:$A$378,"<="&$A21,Питание!$C$14:$C$378,">0"),"")) | Q21: =IF(D21="","",IFERROR(AVERAGEIFS(Питание!$D$14:$D$378,Питание!$A$14:$A$378,">"&$A21-7,Питание!$A$14:$A$378,"<="&$A21,Питание!$D$14:$D$378,">0"),"")) | R21: =IF(O21="","",IFERROR(O21-AVERAGEIFS(Питание!$B$14:$B$378,Питание!$A$14:$A$378,">"&$A21-14,Питание!$A$14:$A$378,"<="&$A21-7,Питание!$B$14:$B$378,">0"),"")) | S21: =IF(R21="","",R21/O21) | T21: =IF(O21="","",O21-StartWeight)
A22: =A21+1 -> 46302 | J22: =IF(C22="","",C22-TargetKcal) | K22: =IF(D22="","",D22-TargetProtein) | L22: =IF(E22="","",E22-TargetFat) | M22: =IF(F22="","",F22-TargetCarb) | N22: =IF(COUNT(C22:F22)<4,"",ROUND(4*D22+9*E22+4*F22-C22,0)) | O22: =IF(B22="","",IFERROR(AVERAGEIFS(Питание!$B$14:$B$378,Питание!$A$14:$A$378,">"&$A22-7,Питание!$A$14:$A$378,"<="&$A22,Питание!$B$14:$B$378,">0"),"")) | P22: =IF(C22="","",IFERROR(AVERAGEIFS(Питание!$C$14:$C$378,Питание!$A$14:$A$378,">"&$A22-7,Питание!$A$14:$A$378,"<="&$A22,Питание!$C$14:$C$378,">0"),"")) | Q22: =IF(D22="","",IFERROR(AVERAGEIFS(Питание!$D$14:$D$378,Питание!$A$14:$A$378,">"&$A22-7,Питание!$A$14:$A$378,"<="&$A22,Питание!$D$14:$D$378,">0"),"")) | R22: =IF(O22="","",IFERROR(O22-AVERAGEIFS(Питание!$B$14:$B$378,Питание!$A$14:$A$378,">"&$A22-14,Питание!$A$14:$A$378,"<="&$A22-7,Питание!$B$14:$B$378,">0"),"")) | S22: =IF(R22="","",R22/O22) | T22: =IF(O22="","",O22-StartWeight)
A23: =A22+1 -> 46303 | J23: =IF(C23="","",C23-TargetKcal) | K23: =IF(D23="","",D23-TargetProtein) | L23: =IF(E23="","",E23-TargetFat) | M23: =IF(F23="","",F23-TargetCarb) | N23: =IF(COUNT(C23:F23)<4,"",ROUND(4*D23+9*E23+4*F23-C23,0)) | O23: =IF(B23="","",IFERROR(AVERAGEIFS(Питание!$B$14:$B$378,Питание!$A$14:$A$378,">"&$A23-7,Питание!$A$14:$A$378,"<="&$A23,Питание!$B$14:$B$378,">0"),"")) | P23: =IF(C23="","",IFERROR(AVERAGEIFS(Питание!$C$14:$C$378,Питание!$A$14:$A$378,">"&$A23-7,Питание!$A$14:$A$378,"<="&$A23,Питание!$C$14:$C$378,">0"),"")) | Q23: =IF(D23="","",IFERROR(AVERAGEIFS(Питание!$D$14:$D$378,Питание!$A$14:$A$378,">"&$A23-7,Питание!$A$14:$A$378,"<="&$A23,Питание!$D$14:$D$378,">0"),"")) | R23: =IF(O23="","",IFERROR(O23-AVERAGEIFS(Питание!$B$14:$B$378,Питание!$A$14:$A$378,">"&$A23-14,Питание!$A$14:$A$378,"<="&$A23-7,Питание!$B$14:$B$378,">0"),"")) | S23: =IF(R23="","",R23/O23) | T23: =IF(O23="","",O23-StartWeight)
A24: =A23+1 -> 46304 | J24: =IF(C24="","",C24-TargetKcal) | K24: =IF(D24="","",D24-TargetProtein) | L24: =IF(E24="","",E24-TargetFat) | M24: =IF(F24="","",F24-TargetCarb) | N24: =IF(COUNT(C24:F24)<4,"",ROUND(4*D24+9*E24+4*F24-C24,0)) | O24: =IF(B24="","",IFERROR(AVERAGEIFS(Питание!$B$14:$B$378,Питание!$A$14:$A$378,">"&$A24-7,Питание!$A$14:$A$378,"<="&$A24,Питание!$B$14:$B$378,">0"),"")) | P24: =IF(C24="","",IFERROR(AVERAGEIFS(Питание!$C$14:$C$378,Питание!$A$14:$A$378,">"&$A24-7,Питание!$A$14:$A$378,"<="&$A24,Питание!$C$14:$C$378,">0"),"")) | Q24: =IF(D24="","",IFERROR(AVERAGEIFS(Питание!$D$14:$D$378,Питание!$A$14:$A$378,">"&$A24-7,Питание!$A$14:$A$378,"<="&$A24,Питание!$D$14:$D$378,">0"),"")) | R24: =IF(O24="","",IFERROR(O24-AVERAGEIFS(Питание!$B$14:$B$378,Питание!$A$14:$A$378,">"&$A24-14,Питание!$A$14:$A$378,"<="&$A24-7,Питание!$B$14:$B$378,">0"),"")) | S24: =IF(R24="","",R24/O24) | T24: =IF(O24="","",O24-StartWeight)
A25: =A24+1 -> 46305 | J25: =IF(C25="","",C25-TargetKcal) | K25: =IF(D25="","",D25-TargetProtein) | L25: =IF(E25="","",E25-TargetFat) | M25: =IF(F25="","",F25-TargetCarb) | N25: =IF(COUNT(C25:F25)<4,"",ROUND(4*D25+9*E25+4*F25-C25,0)) | O25: =IF(B25="","",IFERROR(AVERAGEIFS(Питание!$B$14:$B$378,Питание!$A$14:$A$378,">"&$A25-7,Питание!$A$14:$A$378,"<="&$A25,Питание!$B$14:$B$378,">0"),"")) | P25: =IF(C25="","",IFERROR(AVERAGEIFS(Питание!$C$14:$C$378,Питание!$A$14:$A$378,">"&$A25-7,Питание!$A$14:$A$378,"<="&$A25,Питание!$C$14:$C$378,">0"),"")) | Q25: =IF(D25="","",IFERROR(AVERAGEIFS(Питание!$D$14:$D$378,Питание!$A$14:$A$378,">"&$A25-7,Питание!$A$14:$A$378,"<="&$A25,Питание!$D$14:$D$378,">0"),"")) | R25: =IF(O25="","",IFERROR(O25-AVERAGEIFS(Питание!$B$14:$B$378,Питание!$A$14:$A$378,">"&$A25-14,Питание!$A$14:$A$378,"<="&$A25-7,Питание!$B$14:$B$378,">0"),"")) | S25: =IF(R25="","",R25/O25) | T25: =IF(O25="","",O25-StartWeight)
A26: =A25+1 -> 46306 | J26: =IF(C26="","",C26-TargetKcal) | K26: =IF(D26="","",D26-TargetProtein) | L26: =IF(E26="","",E26-TargetFat) | M26: =IF(F26="","",F26-TargetCarb) | N26: =IF(COUNT(C26:F26)<4,"",ROUND(4*D26+9*E26+4*F26-C26,0)) | O26: =IF(B26="","",IFERROR(AVERAGEIFS(Питание!$B$14:$B$378,Питание!$A$14:$A$378,">"&$A26-7,Питание!$A$14:$A$378,"<="&$A26,Питание!$B$14:$B$378,">0"),"")) | P26: =IF(C26="","",IFERROR(AVERAGEIFS(Питание!$C$14:$C$378,Питание!$A$14:$A$378,">"&$A26-7,Питание!$A$14:$A$378,"<="&$A26,Питание!$C$14:$C$378,">0"),"")) | Q26: =IF(D26="","",IFERROR(AVERAGEIFS(Питание!$D$14:$D$378,Питание!$A$14:$A$378,">"&$A26-7,Питание!$A$14:$A$378,"<="&$A26,Питание!$D$14:$D$378,">0"),"")) | R26: =IF(O26="","",IFERROR(O26-AVERAGEIFS(Питание!$B$14:$B$378,Питание!$A$14:$A$378,">"&$A26-14,Питание!$A$14:$A$378,"<="&$A26-7,Питание!$B$14:$B$378,">0"),"")) | S26: =IF(R26="","",R26/O26) | T26: =IF(O26="","",O26-StartWeight)
A27: =A26+1 -> 46307 | J27: =IF(C27="","",C27-TargetKcal) | K27: =IF(D27="","",D27-TargetProtein) | L27: =IF(E27="","",E27-TargetFat) | M27: =IF(F27="","",F27-TargetCarb) | N27: =IF(COUNT(C27:F27)<4,"",ROUND(4*D27+9*E27+4*F27-C27,0)) | O27: =IF(B27="","",IFERROR(AVERAGEIFS(Питание!$B$14:$B$378,Питание!$A$14:$A$378,">"&$A27-7,Питание!$A$14:$A$378,"<="&$A27,Питание!$B$14:$B$378,">0"),"")) | P27: =IF(C27="","",IFERROR(AVERAGEIFS(Питание!$C$14:$C$378,Питание!$A$14:$A$378,">"&$A27-7,Питание!$A$14:$A$378,"<="&$A27,Питание!$C$14:$C$378,">0"),"")) | Q27: =IF(D27="","",IFERROR(AVERAGEIFS(Питание!$D$14:$D$378,Питание!$A$14:$A$378,">"&$A27-7,Питание!$A$14:$A$378,"<="&$A27,Питание!$D$14:$D$378,">0"),"")) | R27: =IF(O27="","",IFERROR(O27-AVERAGEIFS(Питание!$B$14:$B$378,Питание!$A$14:$A$378,">"&$A27-14,Питание!$A$14:$A$378,"<="&$A27-7,Питание!$B$14:$B$378,">0"),"")) | S27: =IF(R27="","",R27/O27) | T27: =IF(O27="","",O27-StartWeight)
A28: =A27+1 -> 46308 | J28: =IF(C28="","",C28-TargetKcal) | K28: =IF(D28="","",D28-TargetProtein) | L28: =IF(E28="","",E28-TargetFat) | M28: =IF(F28="","",F28-TargetCarb) | N28: =IF(COUNT(C28:F28)<4,"",ROUND(4*D28+9*E28+4*F28-C28,0)) | O28: =IF(B28="","",IFERROR(AVERAGEIFS(Питание!$B$14:$B$378,Питание!$A$14:$A$378,">"&$A28-7,Питание!$A$14:$A$378,"<="&$A28,Питание!$B$14:$B$378,">0"),"")) | P28: =IF(C28="","",IFERROR(AVERAGEIFS(Питание!$C$14:$C$378,Питание!$A$14:$A$378,">"&$A28-7,Питание!$A$14:$A$378,"<="&$A28,Питание!$C$14:$C$378,">0"),"")) | Q28: =IF(D28="","",IFERROR(AVERAGEIFS(Питание!$D$14:$D$378,Питание!$A$14:$A$378,">"&$A28-7,Питание!$A$14:$A$378,"<="&$A28,Питание!$D$14:$D$378,">0"),"")) | R28: =IF(O28="","",IFERROR(O28-AVERAGEIFS(Питание!$B$14:$B$378,Питание!$A$14:$A$378,">"&$A28-14,Питание!$A$14:$A$378,"<="&$A28-7,Питание!$B$14:$B$378,">0"),"")) | S28: =IF(R28="","",R28/O28) | T28: =IF(O28="","",O28-StartWeight)
A29: =A28+1 -> 46309 | J29: =IF(C29="","",C29-TargetKcal) | K29: =IF(D29="","",D29-TargetProtein) | L29: =IF(E29="","",E29-TargetFat) | M29: =IF(F29="","",F29-TargetCarb) | N29: =IF(COUNT(C29:F29)<4,"",ROUND(4*D29+9*E29+4*F29-C29,0)) | O29: =IF(B29="","",IFERROR(AVERAGEIFS(Питание!$B$14:$B$378,Питание!$A$14:$A$378,">"&$A29-7,Питание!$A$14:$A$378,"<="&$A29,Питание!$B$14:$B$378,">0"),"")) | P29: =IF(C29="","",IFERROR(AVERAGEIFS(Питание!$C$14:$C$378,Питание!$A$14:$A$378,">"&$A29-7,Питание!$A$14:$A$378,"<="&$A29,Питание!$C$14:$C$378,">0"),"")) | Q29: =IF(D29="","",IFERROR(AVERAGEIFS(Питание!$D$14:$D$378,Питание!$A$14:$A$378,">"&$A29-7,Питание!$A$14:$A$378,"<="&$A29,Питание!$D$14:$D$378,">0"),"")) | R29: =IF(O29="","",IFERROR(O29-AVERAGEIFS(Питание!$B$14:$B$378,Питание!$A$14:$A$378,">"&$A29-14,Питание!$A$14:$A$378,"<="&$A29-7,Питание!$B$14:$B$378,">0"),"")) | S29: =IF(R29="","",R29/O29) | T29: =IF(O29="","",O29-StartWeight)
A30: =A29+1 -> 46310 | J30: =IF(C30="","",C30-TargetKcal) | K30: =IF(D30="","",D30-TargetProtein) | L30: =IF(E30="","",E30-TargetFat) | M30: =IF(F30="","",F30-TargetCarb) | N30: =IF(COUNT(C30:F30)<4,"",ROUND(4*D30+9*E30+4*F30-C30,0)) | O30: =IF(B30="","",IFERROR(AVERAGEIFS(Питание!$B$14:$B$378,Питание!$A$14:$A$378,">"&$A30-7,Питание!$A$14:$A$378,"<="&$A30,Питание!$B$14:$B$378,">0"),"")) | P30: =IF(C30="","",IFERROR(AVERAGEIFS(Питание!$C$14:$C$378,Питание!$A$14:$A$378,">"&$A30-7,Питание!$A$14:$A$378,"<="&$A30,Питание!$C$14:$C$378,">0"),"")) | Q30: =IF(D30="","",IFERROR(AVERAGEIFS(Питание!$D$14:$D$378,Питание!$A$14:$A$378,">"&$A30-7,Питание!$A$14:$A$378,"<="&$A30,Питание!$D$14:$D$378,">0"),"")) | R30: =IF(O30="","",IFERROR(O30-AVERAGEIFS(Питание!$B$14:$B$378,Питание!$A$14:$A$378,">"&$A30-14,Питание!$A$14:$A$378,"<="&$A30-7,Питание!$B$14:$B$378,">0"),"")) | S30: =IF(R30="","",R30/O30) | T30: =IF(O30="","",O30-StartWeight)
A31: =A30+1 -> 46311 | J31: =IF(C31="","",C31-TargetKcal) | K31: =IF(D31="","",D31-TargetProtein) | L31: =IF(E31="","",E31-TargetFat) | M31: =IF(F31="","",F31-TargetCarb) | N31: =IF(COUNT(C31:F31)<4,"",ROUND(4*D31+9*E31+4*F31-C31,0)) | O31: =IF(B31="","",IFERROR(AVERAGEIFS(Питание!$B$14:$B$378,Питание!$A$14:$A$378,">"&$A31-7,Питание!$A$14:$A$378,"<="&$A31,Питание!$B$14:$B$378,">0"),"")) | P31: =IF(C31="","",IFERROR(AVERAGEIFS(Питание!$C$14:$C$378,Питание!$A$14:$A$378,">"&$A31-7,Питание!$A$14:$A$378,"<="&$A31,Питание!$C$14:$C$378,">0"),"")) | Q31: =IF(D31="","",IFERROR(AVERAGEIFS(Питание!$D$14:$D$378,Питание!$A$14:$A$378,">"&$A31-7,Питание!$A$14:$A$378,"<="&$A31,Питание!$D$14:$D$378,">0"),"")) | R31: =IF(O31="","",IFERROR(O31-AVERAGEIFS(Питание!$B$14:$B$378,Питание!$A$14:$A$378,">"&$A31-14,Питание!$A$14:$A$378,"<="&$A31-7,Питание!$B$14:$B$378,">0"),"")) | S31: =IF(R31="","",R31/O31) | T31: =IF(O31="","",O31-StartWeight)
... A378: =A377+1 -> 46658 | J378: =IF(C378="","",C378-TargetKcal) | K378: =IF(D378="","",D378-TargetProtein) | L378: =IF(E378="","",E378-TargetFat) | M378: =IF(F378="","",F378-TargetCarb) | N378: =IF(COUNT(C378:F378)<4,"",ROUND(4*D378+9*E378+4*F378-C378,0)) | O378: =IF(B378="","",IFERROR(AVERAGEIFS(Питание!$B$14:$B$378,Питание!$A$14:$A$378,">"&$A378-7,Питание!$A$14:$A$378,"<="&$A378,Питание!$B$14:$B$378,">0"),"")) | P378: =IF(C378="","",IFERROR(AVERAGEIFS(Питание!$C$14:$C$378,Питание!$A$14:$A$378,">"&$A378-7,Питание!$A$14:$A$378,"<="&$A378,Питание!$C$14:$C$378,">0"),"")) | Q378: =IF(D378="","",IFERROR(AVERAGEIFS(Питание!$D$14:$D$378,Питание!$A$14:$A$378,">"&$A378-7,Питание!$A$14:$A$378,"<="&$A378,Питание!$D$14:$D$378,">0"),"")) | R378: =IF(O378="","",IFERROR(O378-AVERAGEIFS(Питание!$B$14:$B$378,Питание!$A$14:$A$378,">"&$A378-14,Питание!$A$14:$A$378,"<="&$A378-7,Питание!$B$14:$B$378,">0"),"")) | S378: =IF(R378="","",R378/O378) | T378: =IF(O378="","",O378-StartWeight)

Sheet Тренировки
A1: Журнал тренировок
A2: Вноси каждый рабочий подход отдельной строкой: дата, тренировка, упражнение (список), номер подхода, вес, повторения, RIR. Разминку помечай типом «Разминка». Синие ячейки на жёлтом фоне — ввод. Столбцы J–L считаются сами. Подсказки на следующую тренировку — на листе «Программа тренировок».
A3: 46294 | B3: A | C3: Жим платформы ногами | D3: 1 | E3: 80 | F3: 12 | G3: 2 | H3: Рабочий | I3: ← пример строки (в расчётах не участвует)
A5: Дата | B5: Тренировка | C5: Упражнение | D5: Подход № | E5: Вес, кг | F5: Повторения | G5: RIR | H5: Тип подхода | I5: Комментарий | J5: Объём, кг×повт. | K5: Диапазон по программе | L5: Оценка подхода
A6: 46193 | B6: Ноги | C6: Присед в Смитте | D6: 1 | E6: 30 | F6: 15 | H6: Рабочий | J6: =IF(OR(E6="",F6=""),"",E6*F6) -> 450 | K6: =IF($M6="","",INDEX('Программа тренировок'!$G$6:$G$25,$M6)) | L6: =IF(OR($M6="",$F6="",$G6=""),"",IF($H6="Разминка","Разминка",IF($F6<INDEX('Программа тренировок'!$E$6:$E$25,$M6),"Ниже диапазона",IF(AND($F6>=INDEX('Программа тренировок'!$F$6:$F$25,$M6),$G6>=INDEX('Программа тренировок'!$L$6:$L$25,$M6)),"Верх диапазона: пора добавлять вес",IF($G6<INDEX('Программа тренировок'!$L$6:$L$25,$M6),"RIR ниже цели","В диапазоне"))))) | M6: =IF($C6="","",IFERROR(MATCH($C6,'Программа тренировок'!$C$6:$C$25,0),""))
A7: 46193 | B7: Ноги | C7: Присед в Смитте | D7: 2 | E7: 30 | F7: 15 | H7: Рабочий | J7: =IF(OR(E7="",F7=""),"",E7*F7) -> 450 | K7: =IF($M7="","",INDEX('Программа тренировок'!$G$6:$G$25,$M7)) | L7: =IF(OR($M7="",$F7="",$G7=""),"",IF($H7="Разминка","Разминка",IF($F7<INDEX('Программа тренировок'!$E$6:$E$25,$M7),"Ниже диапазона",IF(AND($F7>=INDEX('Программа тренировок'!$F$6:$F$25,$M7),$G7>=INDEX('Программа тренировок'!$L$6:$L$25,$M7)),"Верх диапазона: пора добавлять вес",IF($G7<INDEX('Программа тренировок'!$L$6:$L$25,$M7),"RIR ниже цели","В диапазоне"))))) | M7: =IF($C7="","",IFERROR(MATCH($C7,'Программа тренировок'!$C$6:$C$25,0),""))
A8: 46193 | B8: Ноги | C8: Присед в Смитте | D8: 3 | E8: 30 | F8: 15 | H8: Рабочий | J8: =IF(OR(E8="",F8=""),"",E8*F8) -> 450 | K8: =IF($M8="","",INDEX('Программа тренировок'!$G$6:$G$25,$M8)) | L8: =IF(OR($M8="",$F8="",$G8=""),"",IF($H8="Разминка","Разминка",IF($F8<INDEX('Программа тренировок'!$E$6:$E$25,$M8),"Ниже диапазона",IF(AND($F8>=INDEX('Программа тренировок'!$F$6:$F$25,$M8),$G8>=INDEX('Программа тренировок'!$L$6:$L$25,$M8)),"Верх диапазона: пора добавлять вес",IF($G8<INDEX('Программа тренировок'!$L$6:$L$25,$M8),"RIR ниже цели","В диапазоне"))))) | M8: =IF($C8="","",IFERROR(MATCH($C8,'Программа тренировок'!$C$6:$C$25,0),""))
A9: 46193 | B9: Ноги | C9: Присед в Смитте | D9: 4 | E9: 30 | F9: 15 | H9: Рабочий | J9: =IF(OR(E9="",F9=""),"",E9*F9) -> 450 | K9: =IF($M9="","",INDEX('Программа тренировок'!$G$6:$G$25,$M9)) | L9: =IF(OR($M9="",$F9="",$G9=""),"",IF($H9="Разминка","Разминка",IF($F9<INDEX('Программа тренировок'!$E$6:$E$25,$M9),"Ниже диапазона",IF(AND($F9>=INDEX('Программа тренировок'!$F$6:$F$25,$M9),$G9>=INDEX('Программа тренировок'!$L$6:$L$25,$M9)),"Верх диапазона: пора добавлять вес",IF($G9<INDEX('Программа тренировок'!$L$6:$L$25,$M9),"RIR ниже цели","В диапазоне"))))) | M9: =IF($C9="","",IFERROR(MATCH($C9,'Программа тренировок'!$C$6:$C$25,0),""))
A10: 46193 | B10: Ноги | C10: Жим платформы ногами | D10: 1 | E10: 70 | F10: 15 | H10: Рабочий | J10: =IF(OR(E10="",F10=""),"",E10*F10) -> 1050 | K10: =IF($M10="","",INDEX('Программа тренировок'!$G$6:$G$25,$M10)) -> 10–12 | L10: =IF(OR($M10="",$F10="",$G10=""),"",IF($H10="Разминка","Разминка",IF($F10<INDEX('Программа тренировок'!$E$6:$E$25,$M10),"Ниже диапазона",IF(AND($F10>=INDEX('Программа тренировок'!$F$6:$F$25,$M10),$G10>=INDEX('Программа тренировок'!$L$6:$L$25,$M10)),"Верх диапазона: пора добавлять вес",IF($G10<INDEX('Программа тренировок'!$L$6:$L$25,$M10),"RIR ниже цели","В диапазоне"))))) | M10: =IF($C10="","",IFERROR(MATCH($C10,'Программа тренировок'!$C$6:$C$25,0),"")) -> 1
A11: 46193 | B11: Ноги | C11: Жим платформы ногами | D11: 2 | E11: 70 | F11: 15 | H11: Рабочий | J11: =IF(OR(E11="",F11=""),"",E11*F11) -> 1050 | K11: =IF($M11="","",INDEX('Программа тренировок'!$G$6:$G$25,$M11)) -> 10–12 | L11: =IF(OR($M11="",$F11="",$G11=""),"",IF($H11="Разминка","Разминка",IF($F11<INDEX('Программа тренировок'!$E$6:$E$25,$M11),"Ниже диапазона",IF(AND($F11>=INDEX('Программа тренировок'!$F$6:$F$25,$M11),$G11>=INDEX('Программа тренировок'!$L$6:$L$25,$M11)),"Верх диапазона: пора добавлять вес",IF($G11<INDEX('Программа тренировок'!$L$6:$L$25,$M11),"RIR ниже цели","В диапазоне"))))) | M11: =IF($C11="","",IFERROR(MATCH($C11,'Программа тренировок'!$C$6:$C$25,0),"")) -> 1
A12: 46193 | B12: Ноги | C12: Жим платформы ногами | D12: 3 | E12: 70 | F12: 15 | H12: Рабочий | J12: =IF(OR(E12="",F12=""),"",E12*F12) -> 1050 | K12: =IF($M12="","",INDEX('Программа тренировок'!$G$6:$G$25,$M12)) -> 10–12 | L12: =IF(OR($M12="",$F12="",$G12=""),"",IF($H12="Разминка","Разминка",IF($F12<INDEX('Программа тренировок'!$E$6:$E$25,$M12),"Ниже диапазона",IF(AND($F12>=INDEX('Программа тренировок'!$F$6:$F$25,$M12),$G12>=INDEX('Программа тренировок'!$L$6:$L$25,$M12)),"Верх диапазона: пора добавлять вес",IF($G12<INDEX('Программа тренировок'!$L$6:$L$25,$M12),"RIR ниже цели","В диапазоне"))))) | M12: =IF($C12="","",IFERROR(MATCH($C12,'Программа тренировок'!$C$6:$C$25,0),"")) -> 1
A13: 46193 | B13: Ноги | C13: Жим платформы ногами | D13: 4 | E13: 70 | F13: 15 | H13: Рабочий | J13: =IF(OR(E13="",F13=""),"",E13*F13) -> 1050 | K13: =IF($M13="","",INDEX('Программа тренировок'!$G$6:$G$25,$M13)) -> 10–12 | L13: =IF(OR($M13="",$F13="",$G13=""),"",IF($H13="Разминка","Разминка",IF($F13<INDEX('Программа тренировок'!$E$6:$E$25,$M13),"Ниже диапазона",IF(AND($F13>=INDEX('Программа тренировок'!$F$6:$F$25,$M13),$G13>=INDEX('Программа тренировок'!$L$6:$L$25,$M13)),"Верх диапазона: пора добавлять вес",IF($G13<INDEX('Программа тренировок'!$L$6:$L$25,$M13),"RIR ниже цели","В диапазоне"))))) | M13: =IF($C13="","",IFERROR(MATCH($C13,'Программа тренировок'!$C$6:$C$25,0),"")) -> 1
A14: 46193 | B14: Ноги | C14: Разгибание ног сидя в тренажере | D14: 1 | E14: 50 | F14: 15 | H14: Рабочий | J14: =IF(OR(E14="",F14=""),"",E14*F14) -> 750 | K14: =IF($M14="","",INDEX('Программа тренировок'!$G$6:$G$25,$M14)) | L14: =IF(OR($M14="",$F14="",$G14=""),"",IF($H14="Разминка","Разминка",IF($F14<INDEX('Программа тренировок'!$E$6:$E$25,$M14),"Ниже диапазона",IF(AND($F14>=INDEX('Программа тренировок'!$F$6:$F$25,$M14),$G14>=INDEX('Программа тренировок'!$L$6:$L$25,$M14)),"Верх диапазона: пора добавлять вес",IF($G14<INDEX('Программа тренировок'!$L$6:$L$25,$M14),"RIR ниже цели","В диапазоне"))))) | M14: =IF($C14="","",IFERROR(MATCH($C14,'Программа тренировок'!$C$6:$C$25,0),""))
A15: 46193 | B15: Ноги | C15: Разгибание ног сидя в тренажере | D15: 2 | E15: 50 | F15: 15 | H15: Рабочий | J15: =IF(OR(E15="",F15=""),"",E15*F15) -> 750 | K15: =IF($M15="","",INDEX('Программа тренировок'!$G$6:$G$25,$M15)) | L15: =IF(OR($M15="",$F15="",$G15=""),"",IF($H15="Разминка","Разминка",IF($F15<INDEX('Программа тренировок'!$E$6:$E$25,$M15),"Ниже диапазона",IF(AND($F15>=INDEX('Программа тренировок'!$F$6:$F$25,$M15),$G15>=INDEX('Программа тренировок'!$L$6:$L$25,$M15)),"Верх диапазона: пора добавлять вес",IF($G15<INDEX('Программа тренировок'!$L$6:$L$25,$M15),"RIR ниже цели","В диапазоне"))))) | M15: =IF($C15="","",IFERROR(MATCH($C15,'Программа тренировок'!$C$6:$C$25,0),""))
A16: 46193 | B16: Ноги | C16: Разгибание ног сидя в тренажере | D16: 3 | E16: 55 | F16: 15 | H16: Рабочий | J16: =IF(OR(E16="",F16=""),"",E16*F16) -> 825 | K16: =IF($M16="","",INDEX('Программа тренировок'!$G$6:$G$25,$M16)) | L16: =IF(OR($M16="",$F16="",$G16=""),"",IF($H16="Разминка","Разминка",IF($F16<INDEX('Программа тренировок'!$E$6:$E$25,$M16),"Ниже диапазона",IF(AND($F16>=INDEX('Программа тренировок'!$F$6:$F$25,$M16),$G16>=INDEX('Программа тренировок'!$L$6:$L$25,$M16)),"Верх диапазона: пора добавлять вес",IF($G16<INDEX('Программа тренировок'!$L$6:$L$25,$M16),"RIR ниже цели","В диапазоне"))))) | M16: =IF($C16="","",IFERROR(MATCH($C16,'Программа тренировок'!$C$6:$C$25,0),""))
A17: 46193 | B17: Ноги | C17: Разгибание ног сидя в тренажере | D17: 4 | E17: 55 | F17: 15 | H17: Рабочий | J17: =IF(OR(E17="",F17=""),"",E17*F17) -> 825 | K17: =IF($M17="","",INDEX('Программа тренировок'!$G$6:$G$25,$M17)) | L17: =IF(OR($M17="",$F17="",$G17=""),"",IF($H17="Разминка","Разминка",IF($F17<INDEX('Программа тренировок'!$E$6:$E$25,$M17),"Ниже диапазона",IF(AND($F17>=INDEX('Программа тренировок'!$F$6:$F$25,$M17),$G17>=INDEX('Программа тренировок'!$L$6:$L$25,$M17)),"Верх диапазона: пора добавлять вес",IF($G17<INDEX('Программа тренировок'!$L$6:$L$25,$M17),"RIR ниже цели","В диапазоне"))))) | M17: =IF($C17="","",IFERROR(MATCH($C17,'Программа тренировок'!$C$6:$C$25,0),""))
... A40: 46200 | B40: Грудь, руки, плечи | C40: На предплечья сидя на скамье: раскатывание штанги | D40: 2 | E40: 15 | F40: 20 | H40: Рабочий | J40: =IF(OR(E40="",F40=""),"",E40*F40) -> 300 | K40: =IF($M40="","",INDEX('Программа тренировок'!$G$6:$G$25,$M40)) | L40: =IF(OR($M40="",$F40="",$G40=""),"",IF($H40="Разминка","Разминка",IF($F40<INDEX('Программа тренировок'!$E$6:$E$25,$M40),"Ниже диапазона",IF(AND($F40>=INDEX('Программа тренировок'!$F$6:$F$25,$M40),$G40>=INDEX('Программа тренировок'!$L$6:$L$25,$M40)),"Верх диапазона: пора добавлять вес",IF($G40<INDEX('Программа тренировок'!$L$6:$L$25,$M40),"RIR ниже цели","В диапазоне"))))) | M40: =IF($C40="","",IFERROR(MATCH($C40,'Программа тренировок'!$C$6:$C$25,0),""))
A41: 46200 | B41: Грудь, руки, плечи | C41: На предплечья сидя на скамье: раскатывание штанги | D41: 3 | E41: 15 | H41: Рабочий | J41: =IF(OR(E41="",F41=""),"",E41*F41) | K41: =IF($M41="","",INDEX('Программа тренировок'!$G$6:$G$25,$M41)) | L41: =IF(OR($M41="",$F41="",$G41=""),"",IF($H41="Разминка","Разминка",IF($F41<INDEX('Программа тренировок'!$E$6:$E$25,$M41),"Ниже диапазона",IF(AND($F41>=INDEX('Программа тренировок'!$F$6:$F$25,$M41),$G41>=INDEX('Программа тренировок'!$L$6:$L$25,$M41)),"Верх диапазона: пора добавлять вес",IF($G41<INDEX('Программа тренировок'!$L$6:$L$25,$M41),"RIR ниже цели","В диапазоне"))))) | M41: =IF($C41="","",IFERROR(MATCH($C41,'Программа тренировок'!$C$6:$C$25,0),""))
A42: 46206 | B42: Спина, руки | C42: Тяга с верхнего блока узким хватом | D42: 1 | E42: 45.5 | F42: 20 | H42: Рабочий | J42: =IF(OR(E42="",F42=""),"",E42*F42) -> 910 | K42: =IF($M42="","",INDEX('Программа тренировок'!$G$6:$G$25,$M42)) | L42: =IF(OR($M42="",$F42="",$G42=""),"",IF($H42="Разминка","Разминка",IF($F42<INDEX('Программа тренировок'!$E$6:$E$25,$M42),"Ниже диапазона",IF(AND($F42>=INDEX('Программа тренировок'!$F$6:$F$25,$M42),$G42>=INDEX('Программа тренировок'!$L$6:$L$25,$M42)),"Верх диапазона: пора добавлять вес",IF($G42<INDEX('Программа тренировок'!$L$6:$L$25,$M42),"RIR ниже цели","В диапазоне"))))) | M42: =IF($C42="","",IFERROR(MATCH($C42,'Программа тренировок'!$C$6:$C$25,0),""))
A43: 46206 | B43: Спина, руки | C43: Тяга с верхнего блока узким хватом | D43: 2 | E43: 54.5 | F43: 10 | H43: Рабочий | J43: =IF(OR(E43="",F43=""),"",E43*F43) -> 545 | K43: =IF($M43="","",INDEX('Программа тренировок'!$G$6:$G$25,$M43)) | L43: =IF(OR($M43="",$F43="",$G43=""),"",IF($H43="Разминка","Разминка",IF($F43<INDEX('Программа тренировок'!$E$6:$E$25,$M43),"Ниже диапазона",IF(AND($F43>=INDEX('Программа тренировок'!$F$6:$F$25,$M43),$G43>=INDEX('Программа тренировок'!$L$6:$L$25,$M43)),"Верх диапазона: пора добавлять вес",IF($G43<INDEX('Программа тренировок'!$L$6:$L$25,$M43),"RIR ниже цели","В диапазоне"))))) | M43: =IF($C43="","",IFERROR(MATCH($C43,'Программа тренировок'!$C$6:$C$25,0),""))
A44: 46206 | B44: Спина, руки | C44: Тяга с верхнего блока узким хватом | D44: 3 | E44: 63.5 | F44: 7 | H44: Рабочий | J44: =IF(OR(E44="",F44=""),"",E44*F44) -> 444.5 | K44: =IF($M44="","",INDEX('Программа тренировок'!$G$6:$G$25,$M44)) | L44: =IF(OR($M44="",$F44="",$G44=""),"",IF($H44="Разминка","Разминка",IF($F44<INDEX('Программа тренировок'!$E$6:$E$25,$M44),"Ниже диапазона",IF(AND($F44>=INDEX('Программа тренировок'!$F$6:$F$25,$M44),$G44>=INDEX('Программа тренировок'!$L$6:$L$25,$M44)),"Верх диапазона: пора добавлять вес",IF($G44<INDEX('Программа тренировок'!$L$6:$L$25,$M44),"RIR ниже цели","В диапазоне"))))) | M44: =IF($C44="","",IFERROR(MATCH($C44,'Программа тренировок'!$C$6:$C$25,0),""))
A45: 46206 | B45: Спина, руки | C45: Тяга с верхнего блока узким хватом | D45: 4 | E45: 63.5 | F45: 3.5 | H45: Рабочий | J45: =IF(OR(E45="",F45=""),"",E45*F45) -> 222.25 | K45: =IF($M45="","",INDEX('Программа тренировок'!$G$6:$G$25,$M45)) | L45: =IF(OR($M45="",$F45="",$G45=""),"",IF($H45="Разминка","Разминка",IF($F45<INDEX('Программа тренировок'!$E$6:$E$25,$M45),"Ниже диапазона",IF(AND($F45>=INDEX('Программа тренировок'!$F$6:$F$25,$M45),$G45>=INDEX('Программа тренировок'!$L$6:$L$25,$M45)),"Верх диапазона: пора добавлять вес",IF($G45<INDEX('Программа тренировок'!$L$6:$L$25,$M45),"RIR ниже цели","В диапазоне"))))) | M45: =IF($C45="","",IFERROR(MATCH($C45,'Программа тренировок'!$C$6:$C$25,0),""))
A46: 46206 | B46: Спина, руки | C46: Сведение в пек-деке | D46: 1 | E46: 27.2 | F46: 20 | H46: Рабочий | J46: =IF(OR(E46="",F46=""),"",E46*F46) -> 544 | K46: =IF($M46="","",INDEX('Программа тренировок'!$G$6:$G$25,$M46)) | L46: =IF(OR($M46="",$F46="",$G46=""),"",IF($H46="Разминка","Разминка",IF($F46<INDEX('Программа тренировок'!$E$6:$E$25,$M46),"Ниже диапазона",IF(AND($F46>=INDEX('Программа тренировок'!$F$6:$F$25,$M46),$G46>=INDEX('Программа тренировок'!$L$6:$L$25,$M46)),"Верх диапазона: пора добавлять вес",IF($G46<INDEX('Программа тренировок'!$L$6:$L$25,$M46),"RIR ниже цели","В диапазоне"))))) | M46: =IF($C46="","",IFERROR(MATCH($C46,'Программа тренировок'!$C$6:$C$25,0),""))
A47: 46206 | B47: Спина, руки | C47: Сведение в пек-деке | D47: 2 | E47: 36.2 | F47: 15 | H47: Рабочий | J47: =IF(OR(E47="",F47=""),"",E47*F47) -> 543 | K47: =IF($M47="","",INDEX('Программа тренировок'!$G$6:$G$25,$M47)) | L47: =IF(OR($M47="",$F47="",$G47=""),"",IF($H47="Разминка","Разминка",IF($F47<INDEX('Программа тренировок'!$E$6:$E$25,$M47),"Ниже диапазона",IF(AND($F47>=INDEX('Программа тренировок'!$F$6:$F$25,$M47),$G47>=INDEX('Программа тренировок'!$L$6:$L$25,$M47)),"Верх диапазона: пора добавлять вес",IF($G47<INDEX('Программа тренировок'!$L$6:$L$25,$M47),"RIR ниже цели","В диапазоне"))))) | M47: =IF($C47="","",IFERROR(MATCH($C47,'Программа тренировок'!$C$6:$C$25,0),""))
A48: 46206 | B48: Спина, руки | C48: Сведение в пек-деке | D48: 3 | E48: 40.8 | F48: 7 | H48: Рабочий | J48: =IF(OR(E48="",F48=""),"",E48*F48) -> 285.6 | K48: =IF($M48="","",INDEX('Программа тренировок'!$G$6:$G$25,$M48)) | L48: =IF(OR($M48="",$F48="",$G48=""),"",IF($H48="Разминка","Разминка",IF($F48<INDEX('Программа тренировок'!$E$6:$E$25,$M48),"Ниже диапазона",IF(AND($F48>=INDEX('Программа тренировок'!$F$6:$F$25,$M48),$G48>=INDEX('Программа тренировок'!$L$6:$L$25,$M48)),"Верх диапазона: пора добавлять вес",IF($G48<INDEX('Программа тренировок'!$L$6:$L$25,$M48),"RIR ниже цели","В диапазоне"))))) | M48: =IF($C48="","",IFERROR(MATCH($C48,'Программа тренировок'!$C$6:$C$25,0),""))
A49: 46206 | B49: Спина, руки | C49: Сведение в пек-деке | D49: 4 | E49: 40.8 | F49: 9 | H49: Рабочий | J49: =IF(OR(E49="",F49=""),"",E49*F49) -> 367.2 | K49: =IF($M49="","",INDEX('Программа тренировок'!$G$6:$G$25,$M49)) | L49: =IF(OR($M49="",$F49="",$G49=""),"",IF($H49="Разминка","Разминка",IF($F49<INDEX('Программа тренировок'!$E$6:$E$25,$M49),"Ниже диапазона",IF(AND($F49>=INDEX('Программа тренировок'!$F$6:$F$25,$M49),$G49>=INDEX('Программа тренировок'!$L$6:$L$25,$M49)),"Верх диапазона: пора добавлять вес",IF($G49<INDEX('Программа тренировок'!$L$6:$L$25,$M49),"RIR ниже цели","В диапазоне"))))) | M49: =IF($C49="","",IFERROR(MATCH($C49,'Программа тренировок'!$C$6:$C$25,0),""))
A50: 46206 | B50: Спина, руки | C50: Жим лежа | D50: 1 | E50: 40 | F50: 10 | H50: Рабочий | J50: =IF(OR(E50="",F50=""),"",E50*F50) -> 400 | K50: =IF($M50="","",INDEX('Программа тренировок'!$G$6:$G$25,$M50)) | L50: =IF(OR($M50="",$F50="",$G50=""),"",IF($H50="Разминка","Разминка",IF($F50<INDEX('Программа тренировок'!$E$6:$E$25,$M50),"Ниже диапазона",IF(AND($F50>=INDEX('Программа тренировок'!$F$6:$F$25,$M50),$G50>=INDEX('Программа тренировок'!$L$6:$L$25,$M50)),"Верх диапазона: пора добавлять вес",IF($G50<INDEX('Программа тренировок'!$L$6:$L$25,$M50),"RIR ниже цели","В диапазоне"))))) | M50: =IF($C50="","",IFERROR(MATCH($C50,'Программа тренировок'!$C$6:$C$25,0),""))
A51: 46206 | B51: Спина, руки | C51: Жим лежа | D51: 2 | E51: 40 | F51: 8 | H51: Рабочий | J51: =IF(OR(E51="",F51=""),"",E51*F51) -> 320 | K51: =IF($M51="","",INDEX('Программа тренировок'!$G$6:$G$25,$M51)) | L51: =IF(OR($M51="",$F51="",$G51=""),"",IF($H51="Разминка","Разминка",IF($F51<INDEX('Программа тренировок'!$E$6:$E$25,$M51),"Ниже диапазона",IF(AND($F51>=INDEX('Программа тренировок'!$F$6:$F$25,$M51),$G51>=INDEX('Программа тренировок'!$L$6:$L$25,$M51)),"Верх диапазона: пора добавлять вес",IF($G51<INDEX('Программа тренировок'!$L$6:$L$25,$M51),"RIR ниже цели","В диапазоне"))))) | M51: =IF($C51="","",IFERROR(MATCH($C51,'Программа тренировок'!$C$6:$C$25,0),""))
A52: 46206 | B52: Спина, руки | C52: Жим лежа | D52: 3 | E52: 40 | F52: 6 | H52: Рабочий | J52: =IF(OR(E52="",F52=""),"",E52*F52) -> 240 | K52: =IF($M52="","",INDEX('Программа тренировок'!$G$6:$G$25,$M52)) | L52: =IF(OR($M52="",$F52="",$G52=""),"",IF($H52="Разминка","Разминка",IF($F52<INDEX('Программа тренировок'!$E$6:$E$25,$M52),"Ниже диапазона",IF(AND($F52>=INDEX('Программа тренировок'!$F$6:$F$25,$M52),$G52>=INDEX('Программа тренировок'!$L$6:$L$25,$M52)),"Верх диапазона: пора добавлять вес",IF($G52<INDEX('Программа тренировок'!$L$6:$L$25,$M52),"RIR ниже цели","В диапазоне"))))) | M52: =IF($C52="","",IFERROR(MATCH($C52,'Программа тренировок'!$C$6:$C$25,0),""))
A53: 46206 | B53: Спина, руки | C53: Жим лежа | D53: 4 | E53: 40 | F53: 6 | H53: Рабочий | J53: =IF(OR(E53="",F53=""),"",E53*F53) -> 240 | K53: =IF($M53="","",INDEX('Программа тренировок'!$G$6:$G$25,$M53)) | L53: =IF(OR($M53="",$F53="",$G53=""),"",IF($H53="Разминка","Разминка",IF($F53<INDEX('Программа тренировок'!$E$6:$E$25,$M53),"Ниже диапазона",IF(AND($F53>=INDEX('Программа тренировок'!$F$6:$F$25,$M53),$G53>=INDEX('Программа тренировок'!$L$6:$L$25,$M53)),"Верх диапазона: пора добавлять вес",IF($G53<INDEX('Программа тренировок'!$L$6:$L$25,$M53),"RIR ниже цели","В диапазоне"))))) | M53: =IF($C53="","",IFERROR(MATCH($C53,'Программа тренировок'!$C$6:$C$25,0),""))
... A110: 46226 | B110: Грудь | C110: Баттерфляй (тренажер) | D110: 4 | E110: 40 | F110: 8 | H110: Рабочий | J110: =IF(OR(E110="",F110=""),"",E110*F110) -> 320 | K110: =IF($M110="","",INDEX('Программа тренировок'!$G$6:$G$25,$M110)) | L110: =IF(OR($M110="",$F110="",$G110=""),"",IF($H110="Разминка","Разминка",IF($F110<INDEX('Программа тренировок'!$E$6:$E$25,$M110),"Ниже диапазона",IF(AND($F110>=INDEX('Программа тренировок'!$F$6:$F$25,$M110),$G110>=INDEX('Программа тренировок'!$L$6:$L$25,$M110)),"Верх диапазона: пора добавлять вес",IF($G110<INDEX('Программа тренировок'!$L$6:$L$25,$M110),"RIR ниже цели","В диапазоне"))))) | M110: =IF($C110="","",IFERROR(MATCH($C110,'Программа тренировок'!$C$6:$C$25,0),""))
A111: 31.02.2026 | C111: Жим платформы ногами | D111: 1 | E111: 80 | F111: 12 | J111: =IF(OR(E111="",F111=""),"",E111*F111) -> 960 | K111: =IF($M111="","",INDEX('Программа тренировок'!$G$6:$G$25,$M111)) -> 10–12 | L111: =IF(OR($M111="",$F111="",$G111=""),"",IF($H111="Разминка","Разминка",IF($F111<INDEX('Программа тренировок'!$E$6:$E$25,$M111),"Ниже диапазона",IF(AND($F111>=INDEX('Программа тренировок'!$F$6:$F$25,$M111),$G111>=INDEX('Программа тренировок'!$L$6:$L$25,$M111)),"Верх диапазона: пора добавлять вес",IF($G111<INDEX('Программа тренировок'!$L$6:$L$25,$M111),"RIR ниже цели","В диапазоне"))))) | M111: =IF($C111="","",IFERROR(MATCH($C111,'Программа тренировок'!$C$6:$C$25,0),"")) -> 1
A112: 46226 | C112: Йога | D112: 1 | E112: 0 | F112: 30 | J112: =IF(OR(E112="",F112=""),"",E112*F112) -> 0 | K112: =IF($M112="","",INDEX('Программа тренировок'!$G$6:$G$25,$M112)) | L112: =IF(OR($M112="",$F112="",$G112=""),"",IF($H112="Разминка","Разминка",IF($F112<INDEX('Программа тренировок'!$E$6:$E$25,$M112),"Ниже диапазона",IF(AND($F112>=INDEX('Программа тренировок'!$F$6:$F$25,$M112),$G112>=INDEX('Программа тренировок'!$L$6:$L$25,$M112)),"Верх диапазона: пора добавлять вес",IF($G112<INDEX('Программа тренировок'!$L$6:$L$25,$M112),"RIR ниже цели","В диапазоне"))))) | M112: =IF($C112="","",IFERROR(MATCH($C112,'Программа тренировок'!$C$6:$C$25,0),""))
J113: =IF(OR(E113="",F113=""),"",E113*F113) | K113: =IF($M113="","",INDEX('Программа тренировок'!$G$6:$G$25,$M113)) | L113: =IF(OR($M113="",$F113="",$G113=""),"",IF($H113="Разминка","Разминка",IF($F113<INDEX('Программа тренировок'!$E$6:$E$25,$M113),"Ниже диапазона",IF(AND($F113>=INDEX('Программа тренировок'!$F$6:$F$25,$M113),$G113>=INDEX('Программа тренировок'!$L$6:$L$25,$M113)),"Верх диапазона: пора добавлять вес",IF($G113<INDEX('Программа тренировок'!$L$6:$L$25,$M113),"RIR ниже цели","В диапазоне"))))) | M113: =IF($C113="","",IFERROR(MATCH($C113,'Программа тренировок'!$C$6:$C$25,0),""))
J114: =IF(OR(E114="",F114=""),"",E114*F114) | K114: =IF($M114="","",INDEX('Программа тренировок'!$G$6:$G$25,$M114)) | L114: =IF(OR($M114="",$F114="",$G114=""),"",IF($H114="Разминка","Разминка",IF($F114<INDEX('Программа тренировок'!$E$6:$E$25,$M114),"Ниже диапазона",IF(AND($F114>=INDEX('Программа тренировок'!$F$6:$F$25,$M114),$G114>=INDEX('Программа тренировок'!$L$6:$L$25,$M114)),"Верх диапазона: пора добавлять вес",IF($G114<INDEX('Программа тренировок'!$L$6:$L$25,$M114),"RIR ниже цели","В диапазоне"))))) | M114: =IF($C114="","",IFERROR(MATCH($C114,'Программа тренировок'!$C$6:$C$25,0),""))
J115: =IF(OR(E115="",F115=""),"",E115*F115) | K115: =IF($M115="","",INDEX('Программа тренировок'!$G$6:$G$25,$M115)) | L115: =IF(OR($M115="",$F115="",$G115=""),"",IF($H115="Разминка","Разминка",IF($F115<INDEX('Программа тренировок'!$E$6:$E$25,$M115),"Ниже диапазона",IF(AND($F115>=INDEX('Программа тренировок'!$F$6:$F$25,$M115),$G115>=INDEX('Программа тренировок'!$L$6:$L$25,$M115)),"Верх диапазона: пора добавлять вес",IF($G115<INDEX('Программа тренировок'!$L$6:$L$25,$M115),"RIR ниже цели","В диапазоне"))))) | M115: =IF($C115="","",IFERROR(MATCH($C115,'Программа тренировок'!$C$6:$C$25,0),""))
J116: =IF(OR(E116="",F116=""),"",E116*F116) | K116: =IF($M116="","",INDEX('Программа тренировок'!$G$6:$G$25,$M116)) | L116: =IF(OR($M116="",$F116="",$G116=""),"",IF($H116="Разминка","Разминка",IF($F116<INDEX('Программа тренировок'!$E$6:$E$25,$M116),"Ниже диапазона",IF(AND($F116>=INDEX('Программа тренировок'!$F$6:$F$25,$M116),$G116>=INDEX('Программа тренировок'!$L$6:$L$25,$M116)),"Верх диапазона: пора добавлять вес",IF($G116<INDEX('Программа тренировок'!$L$6:$L$25,$M116),"RIR ниже цели","В диапазоне"))))) | M116: =IF($C116="","",IFERROR(MATCH($C116,'Программа тренировок'!$C$6:$C$25,0),""))
J117: =IF(OR(E117="",F117=""),"",E117*F117) | K117: =IF($M117="","",INDEX('Программа тренировок'!$G$6:$G$25,$M117)) | L117: =IF(OR($M117="",$F117="",$G117=""),"",IF($H117="Разминка","Разминка",IF($F117<INDEX('Программа тренировок'!$E$6:$E$25,$M117),"Ниже диапазона",IF(AND($F117>=INDEX('Программа тренировок'!$F$6:$F$25,$M117),$G117>=INDEX('Программа тренировок'!$L$6:$L$25,$M117)),"Верх диапазона: пора добавлять вес",IF($G117<INDEX('Программа тренировок'!$L$6:$L$25,$M117),"RIR ниже цели","В диапазоне"))))) | M117: =IF($C117="","",IFERROR(MATCH($C117,'Программа тренировок'!$C$6:$C$25,0),""))
J118: =IF(OR(E118="",F118=""),"",E118*F118) | K118: =IF($M118="","",INDEX('Программа тренировок'!$G$6:$G$25,$M118)) | L118: =IF(OR($M118="",$F118="",$G118=""),"",IF($H118="Разминка","Разминка",IF($F118<INDEX('Программа тренировок'!$E$6:$E$25,$M118),"Ниже диапазона",IF(AND($F118>=INDEX('Программа тренировок'!$F$6:$F$25,$M118),$G118>=INDEX('Программа тренировок'!$L$6:$L$25,$M118)),"Верх диапазона: пора добавлять вес",IF($G118<INDEX('Программа тренировок'!$L$6:$L$25,$M118),"RIR ниже цели","В диапазоне"))))) | M118: =IF($C118="","",IFERROR(MATCH($C118,'Программа тренировок'!$C$6:$C$25,0),""))
J119: =IF(OR(E119="",F119=""),"",E119*F119) | K119: =IF($M119="","",INDEX('Программа тренировок'!$G$6:$G$25,$M119)) | L119: =IF(OR($M119="",$F119="",$G119=""),"",IF($H119="Разминка","Разминка",IF($F119<INDEX('Программа тренировок'!$E$6:$E$25,$M119),"Ниже диапазона",IF(AND($F119>=INDEX('Программа тренировок'!$F$6:$F$25,$M119),$G119>=INDEX('Программа тренировок'!$L$6:$L$25,$M119)),"Верх диапазона: пора добавлять вес",IF($G119<INDEX('Программа тренировок'!$L$6:$L$25,$M119),"RIR ниже цели","В диапазоне"))))) | M119: =IF($C119="","",IFERROR(MATCH($C119,'Программа тренировок'!$C$6:$C$25,0),""))
...

Sheet Программа тренировок
A1: Программа тренировок: Full Body A / B / C (3 раза в неделю, через день)
A2: Синие ячейки на жёлтом фоне — параметры, их можно править (стартовые веса, диапазоны, шаги). Столбцы R–W считаются сами по журналу на листе «Тренировки» и подсказывают вес на следующую тренировку. Порядок недели, например: Пн A — Ср B — Пт C.
A3: RIR (Reps In Reserve, повторения в запасе): RIR 0 = больше ни одного качественного повторения сделать нельзя (отказ). RIR 1 = мог бы сделать ещё ≈1 повторение. RIR 2 = ещё ≈2. RIR 3 = ещё ≈3. RIR 4 и выше = слишком легко. Сомневаешься между двумя цифрами — записывай меньшую. Разминочные подходы отмечай типом «Разминка» — они не участвуют в подсказках.
A5: День | B5: № | C5: Упражнение | D5: Подходы | E5: Повт. от | F5: Повт. до | G5: Повторения | H5: Стартовый вес, кг | I5: Отдых | J5: RIR нед. 1–3 (мин.) | K5: RIR с нед. 4 (мин.) | L5: Мин. RIR сейчас | M5: Целевой RIR сейчас | N5: Шаг веса, кг | O5: Правило прогрессии | P5: Почему такой стартовый вес | Q5: Условия / комментарий | R5: Последняя тренировка | S5: Вес тогда, кг | T5: Мин. повторов | U5: Мин. RIR | V5: Подсказка на следующую | W5: Вес на следующую, кг
A6: A | B6: 1 | C6: Жим платформы ногами | D6: 3 | E6: 10 | F6: 12 | G6: =E6&"–"&F6 -> 10–12 | H6: 80 | I6: 2–3 мин | J6: 2 | K6: 1 | L6: =IF(WeekNo<=AdaptWeeks,J6,K6) -> 2 | M6: ="RIR "&L6&"–"&(L6+1) -> RIR 2–3 | N6: 5 | O6: Двойная прогрессия: во всех рабочих подходах достигнут верх диапазона при RIR не ниже цели → +шаг веса и снова с нижней границы. Нижняя граница не набрана → −1 шаг или больше отдыха. | P6: 20.06: 70×15 четыре подхода без падения повторений — вес явно не предельный. Для 10–12 при RIR 2–3 беру 80 кг (оценка). В 1-м подходе проверь RIR: если RIR 4+, добавь 5–10 кг сразу. | Q6: Ноги на середине платформы, поясница прижата к спинке, колени не «падают» внутрь. Опускай до комфортного сгибания, без отрыва таза. | R6: =IF(COUNTIF(Тренировки!$C$6:$C$2005,$C6)=0,"",_xlfn.MAXIFS(Тренировки!$A$6:$A$2005,Тренировки!$C$6:$C$2005,$C6)) -> 46193 | S6: =IF($R6="","",_xlfn.MAXIFS(Тренировки!$E$6:$E$2005,Тренировки!$C$6:$C$2005,$C6,Тренировки!$A$6:$A$2005,$R6,Тренировки!$H$6:$H$2005,"<>Разминка")) -> 70 | T6: =IF($R6="","",_xlfn.MINIFS(Тренировки!$F$6:$F$2005,Тренировки!$C$6:$C$2005,$C6,Тренировки!$A$6:$A$2005,$R6,Тренировки!$H$6:$H$2005,"<>Разминка",Тренировки!$F$6:$F$2005,">0")) -> 15 | U6: =IF($R6="","",IF(COUNTIFS(Тренировки!$C$6:$C$2005,$C6,Тренировки!$A$6:$A$2005,$R6,Тренировки!$H$6:$H$2005,"<>Разминка",Тренировки!$G$6:$G$2005,">=0")=0,"",_xlfn.MINIFS(Тренировки!$G$6:$G$2005,Тренировки!$C$6:$C$2005,$C6,Тренировки!$A$6:$A$2005,$R6,Тренировки!$H$6:$H$2005,"<>Разминка",Тренировки!$G$6:$G$2005,">=0"))) | V6: =IF($R6="","Нет данных: начни со стартового веса",IF($U6="","Внеси RIR в журнал",IF($T6<$E6,"Уменьшить вес или увеличить отдых",IF(AND($T6>=$F6,$U6>=$L6),"Увеличить вес",IF($U6>=$L6+2,"Увеличить вес (RIR слишком высокий — вес занижен)",IF($U6<$L6,"Оставить вес; останавливайся раньше (RIR ниже цели)","Оставить вес, добирай повторения")))))) -> Внеси RIR в журнал | W6: =IF($R6="",$H6,IF(LEFT($V6,9)="Увеличить",$S6+$N6,IF(LEFT($V6,9)="Уменьшить",MAX(0,$S6-$N6),$S6))) -> 70
A7: A | B7: 2 | C7: Жим в тренажёре сидя (грудь) | D7: 3 | E7: 8 | F7: 10 | G7: =E7&"–"&F7 -> 8–10 | H7: 30 | I7: 2–3 мин | J7: 2 | K7: 2 | L7: =IF(WeekNo<=AdaptWeeks,J7,K7) -> 2 | M7: ="RIR "&L7&"–"&(L7+1) -> RIR 2–3 | N7: 2.5 | O7: Двойная прогрессия: во всех рабочих подходах достигнут верх диапазона при RIR не ниже цели → +шаг веса и снова с нижней границы. Нижняя граница не набрана → −1 шаг или больше отдыха. | P7: 23.07: 30×15 и 35×8/8/8. Ровные 8 повторений намекают на RIR ≈1–2 на 35 кг, поэтому старт ниже — 30 кг: запас на адаптацию. | Q7: Нейтральный/полунейтральный хват, локти ≈45° к корпусу, амплитуда без глубокого растяжения. Боль в плече — стоп, замени на тренажёр с другой траекторией. Если минимальный шаг у тебя 5 кг — сначала добавляй повторения. | R7: =IF(COUNTIF(Тренировки!$C$6:$C$2005,$C7)=0,"",_xlfn.MAXIFS(Тренировки!$A$6:$A$2005,Тренировки!$C$6:$C$2005,$C7)) | S7: =IF($R7="","",_xlfn.MAXIFS(Тренировки!$E$6:$E$2005,Тренировки!$C$6:$C$2005,$C7,Тренировки!$A$6:$A$2005,$R7,Тренировки!$H$6:$H$2005,"<>Разминка")) | T7: =IF($R7="","",_xlfn.MINIFS(Тренировки!$F$6:$F$2005,Тренировки!$C$6:$C$2005,$C7,Тренировки!$A$6:$A$2005,$R7,Тренировки!$H$6:$H$2005,"<>Разминка",Тренировки!$F$6:$F$2005,">0")) | U7: =IF($R7="","",IF(COUNTIFS(Тренировки!$C$6:$C$2005,$C7,Тренировки!$A$6:$A$2005,$R7,Тренировки!$H$6:$H$2005,"<>Разминка",Тренировки!$G$6:$G$2005,">=0")=0,"",_xlfn.MINIFS(Тренировки!$G$6:$G$2005,Тренировки!$C$6:$C$2005,$C7,Тренировки!$A$6:$A$2005,$R7,Тренировки!$H$6:$H$2005,"<>Разминка",Тренировки!$G$6:$G$2005,">=0"))) | V7: =IF($R7="","Нет данных: начни со стартового веса",IF($U7="","Внеси RIR в журнал",IF($T7<$E7,"Уменьшить вес или увеличить отдых",IF(AND($T7>=$F7,$U7>=$L7),"Увеличить вес",IF($U7>=$L7+2,"Увеличить вес (RIR слишком высокий — вес занижен)",IF($U7<$L7,"Оставить вес; останавливайся раньше (RIR ниже цели)","Оставить вес, добирай повторения")))))) -> Нет данных: начни со стартового веса | W7: =IF($R7="",$H7,IF(LEFT($V7,9)="Увеличить",$S7+$N7,IF(LEFT($V7,9)="Уменьшить",MAX(0,$S7-$N7),$S7))) -> 30
A8: A | B8: 3 | C8: Горизонтальная тяга в блоке (нейтральный хват) | D8: 3 | E8: 10 | F8: 12 | G8: =E8&"–"&F8 -> 10–12 | H8: 40 | I8: 2 мин | J8: 2 | K8: 1 | L8: =IF(WeekNo<=AdaptWeeks,J8,K8) -> 2 | M8: ="RIR "&L8&"–"&(L8+1) -> RIR 2–3 | N8: 2.5 | O8: Двойная прогрессия: во всех рабочих подходах достигнут верх диапазона при RIR не ниже цели → +шаг веса и снова с нижней границы. Нижняя граница не набрана → −1 шаг или больше отдыха. | P8: Истории по этому упражнению нет — старт по оценке 40 кг (немного ниже рабочего веса тяги верхнего блока 54,5×10). Первая тренировка — калибровка RIR. | Q8: Корпус неподвижен, тяни к низу живота, без раскачки поясницей. Лопатки сводить плавно. | R8: =IF(COUNTIF(Тренировки!$C$6:$C$2005,$C8)=0,"",_xlfn.MAXIFS(Тренировки!$A$6:$A$2005,Тренировки!$C$6:$C$2005,$C8)) | S8: =IF($R8="","",_xlfn.MAXIFS(Тренировки!$E$6:$E$2005,Тренировки!$C$6:$C$2005,$C8,Тренировки!$A$6:$A$2005,$R8,Тренировки!$H$6:$H$2005,"<>Разминка")) | T8: =IF($R8="","",_xlfn.MINIFS(Тренировки!$F$6:$F$2005,Тренировки!$C$6:$C$2005,$C8,Тренировки!$A$6:$A$2005,$R8,Тренировки!$H$6:$H$2005,"<>Разминка",Тренировки!$F$6:$F$2005,">0")) | U8: =IF($R8="","",IF(COUNTIFS(Тренировки!$C$6:$C$2005,$C8,Тренировки!$A$6:$A$2005,$R8,Тренировки!$H$6:$H$2005,"<>Разминка",Тренировки!$G$6:$G$2005,">=0")=0,"",_xlfn.MINIFS(Тренировки!$G$6:$G$2005,Тренировки!$C$6:$C$2005,$C8,Тренировки!$A$6:$A$2005,$R8,Тренировки!$H$6:$H$2005,"<>Разминка",Тренировки!$G$6:$G$2005,">=0"))) | V8: =IF($R8="","Нет данных: начни со стартового веса",IF($U8="","Внеси RIR в журнал",IF($T8<$E8,"Уменьшить вес или увеличить отдых",IF(AND($T8>=$F8,$U8>=$L8),"Увеличить вес",IF($U8>=$L8+2,"Увеличить вес (RIR слишком высокий — вес занижен)",IF($U8<$L8,"Оставить вес; останавливайся раньше (RIR ниже цели)","Оставить вес, добирай повторения")))))) -> Нет данных: начни со стартового веса | W8: =IF($R8="",$H8,IF(LEFT($V8,9)="Увеличить",$S8+$N8,IF(LEFT($V8,9)="Уменьшить",MAX(0,$S8-$N8),$S8))) -> 40
A9: A | B9: 4 | C9: Сгибание ног лёжа | D9: 3 | E9: 10 | F9: 12 | G9: =E9&"–"&F9 -> 10–12 | H9: 25 | I9: 90 сек | J9: 2 | K9: 1 | L9: =IF(WeekNo<=AdaptWeeks,J9,K9) -> 2 | M9: ="RIR "&L9&"–"&(L9+1) -> RIR 2–3 | N9: 2.5 | O9: Изоляция: сначала добавляй повторения до верха диапазона; вес +минимальный шаг, только когда верх во всех подходах и RIR не ниже цели. Если шаг больше ~10% веса — сначала +1–2 повтора сверх верха. | P9: 20.06: 30/25/25/20 кг по 15 повторений — вес при 15 повт. ≈25. Для 10–12 при RIR 2 старт 25 кг. | Q9: Таз прижат к скамье, без прогиба в пояснице; опускай медленно (2–3 с). | R9: =IF(COUNTIF(Тренировки!$C$6:$C$2005,$C9)=0,"",_xlfn.MAXIFS(Тренировки!$A$6:$A$2005,Тренировки!$C$6:$C$2005,$C9)) | S9: =IF($R9="","",_xlfn.MAXIFS(Тренировки!$E$6:$E$2005,Тренировки!$C$6:$C$2005,$C9,Тренировки!$A$6:$A$2005,$R9,Тренировки!$H$6:$H$2005,"<>Разминка")) | T9: =IF($R9="","",_xlfn.MINIFS(Тренировки!$F$6:$F$2005,Тренировки!$C$6:$C$2005,$C9,Тренировки!$A$6:$A$2005,$R9,Тренировки!$H$6:$H$2005,"<>Разминка",Тренировки!$F$6:$F$2005,">0")) | U9: =IF($R9="","",IF(COUNTIFS(Тренировки!$C$6:$C$2005,$C9,Тренировки!$A$6:$A$2005,$R9,Тренировки!$H$6:$H$2005,"<>Разминка",Тренировки!$G$6:$G$2005,">=0")=0,"",_xlfn.MINIFS(Тренировки!$G$6:$G$2005,Тренировки!$C$6:$C$2005,$C9,Тренировки!$A$6:$A$2005,$R9,Тренировки!$H$6:$H$2005,"<>Разминка",Тренировки!$G$6:$G$2005,">=0"))) | V9: =IF($R9="","Нет данных: начни со стартового веса",IF($U9="","Внеси RIR в журнал",IF($T9<$E9,"Уменьшить вес или увеличить отдых",IF(AND($T9>=$F9,$U9>=$L9),"Увеличить вес",IF($U9>=$L9+2,"Увеличить вес (RIR слишком высокий — вес занижен)",IF($U9<$L9,"Оставить вес; останавливайся раньше (RIR ниже цели)","Оставить вес, добирай повторения")))))) -> Нет данных: начни со стартового веса | W9: =IF($R9="",$H9,IF(LEFT($V9,9)="Увеличить",$S9+$N9,IF(LEFT($V9,9)="Уменьшить",MAX(0,$S9-$N9),$S9))) -> 25
A10: A | B10: 5 | C10: Жим носками на платформе (икры) | D10: 3 | E10: 12 | F10: 15 | G10: =E10&"–"&F10 -> 12–15 | H10: 50 | I10: 60–90 сек | J10: 2 | K10: 1 | L10: =IF(WeekNo<=AdaptWeeks,J10,K10) -> 2 | M10: ="RIR "&L10&"–"&(L10+1) -> RIR 2–3 | N10: 5 | O10: Изоляция: сначала добавляй повторения до верха диапазона; вес +минимальный шаг, только когда верх во всех подходах и RIR не ниже цели. Если шаг больше ~10% веса — сначала +1–2 повтора сверх верха. | P10: Истории нет — оценка 50 кг (заметно ниже веса жима ногами). Проверь RIR в первом подходе. | Q10: Полная амплитуда: пауза 1 с внизу и вверху, колени почти прямые. | R10: =IF(COUNTIF(Тренировки!$C$6:$C$2005,$C10)=0,"",_xlfn.MAXIFS(Тренировки!$A$6:$A$2005,Тренировки!$C$6:$C$2005,$C10)) | S10: =IF($R10="","",_xlfn.MAXIFS(Тренировки!$E$6:$E$2005,Тренировки!$C$6:$C$2005,$C10,Тренировки!$A$6:$A$2005,$R10,Тренировки!$H$6:$H$2005,"<>Разминка")) | T10: =IF($R10="","",_xlfn.MINIFS(Тренировки!$F$6:$F$2005,Тренировки!$C$6:$C$2005,$C10,Тренировки!$A$6:$A$2005,$R10,Тренировки!$H$6:$H$2005,"<>Разминка",Тренировки!$F$6:$F$2005,">0")) | U10: =IF($R10="","",IF(COUNTIFS(Тренировки!$C$6:$C$2005,$C10,Тренировки!$A$6:$A$2005,$R10,Тренировки!$H$6:$H$2005,"<>Разминка",Тренировки!$G$6:$G$2005,">=0")=0,"",_xlfn.MINIFS(Тренировки!$G$6:$G$2005,Тренировки!$C$6:$C$2005,$C10,Тренировки!$A$6:$A$2005,$R10,Тренировки!$H$6:$H$2005,"<>Разминка",Тренировки!$G$6:$G$2005,">=0"))) | V10: =IF($R10="","Нет данных: начни со стартового веса",IF($U10="","Внеси RIR в журнал",IF($T10<$E10,"Уменьшить вес или увеличить отдых",IF(AND($T10>=$F10,$U10>=$L10),"Увеличить вес",IF($U10>=$L10+2,"Увеличить вес (RIR слишком высокий — вес занижен)",IF($U10<$L10,"Оставить вес; останавливайся раньше (RIR ниже цели)","Оставить вес, добирай повторения")))))) -> Нет данных: начни со стартового веса | W10: =IF($R10="",$H10,IF(LEFT($V10,9)="Увеличить",$S10+$N10,IF(LEFT($V10,9)="Уменьшить",MAX(0,$S10-$N10),$S10))) -> 50
A11: A | B11: 6 | C11: Pallof press (антиротация, блок) | D11: 3 | E11: 10 | F11: 12 | G11: =E11&"–"&F11 -> 10–12 | H11: 10 | I11: 60 сек | J11: 3 | K11: 2 | L11: =IF(WeekNo<=AdaptWeeks,J11,K11) -> 3 | M11: ="RIR "&L11&"–"&(L11+1) -> RIR 3–4 | N11: 2.5 | O11: Изоляция: сначала добавляй повторения до верха диапазона; вес +минимальный шаг, только когда верх во всех подходах и RIR не ниже цели. Если шаг больше ~10% веса — сначала +1–2 повтора сверх верха. | P11: Истории нет — лёгкий вес 10 кг (оценка): цель — стабилизация корпуса, а не тоннаж. Повторения считаются на сторону. | Q11: Безопасный вариант для корпуса при склонности к зажимам в пояснице: корпус не вращается, поясница нейтральна. Не заменяй скручиваниями с весом. | R11: =IF(COUNTIF(Тренировки!$C$6:$C$2005,$C11)=0,"",_xlfn.MAXIFS(Тренировки!$A$6:$A$2005,Тренировки!$C$6:$C$2005,$C11)) | S11: =IF($R11="","",_xlfn.MAXIFS(Тренировки!$E$6:$E$2005,Тренировки!$C$6:$C$2005,$C11,Тренировки!$A$6:$A$2005,$R11,Тренировки!$H$6:$H$2005,"<>Разминка")) | T11: =IF($R11="","",_xlfn.MINIFS(Тренировки!$F$6:$F$2005,Тренировки!$C$6:$C$2005,$C11,Тренировки!$A$6:$A$2005,$R11,Тренировки!$H$6:$H$2005,"<>Разминка",Тренировки!$F$6:$F$2005,">0")) | U11: =IF($R11="","",IF(COUNTIFS(Тренировки!$C$6:$C$2005,$C11,Тренировки!$A$6:$A$2005,$R11,Тренировки!$H$6:$H$2005,"<>Разминка",Тренировки!$G$6:$G$2005,">=0")=0,"",_xlfn.MINIFS(Тренировки!$G$6:$G$2005,Тренировки!$C$6:$C$2005,$C11,Тренировки!$A$6:$A$2005,$R11,Тренировки!$H$6:$H$2005,"<>Разминка",Тренировки!$G$6:$G$2005,">=0"))) | V11: =IF($R11="","Нет данных: начни со стартового веса",IF($U11="","Внеси RIR в журнал",IF($T11<$E11,"Уменьшить вес или увеличить отдых",IF(AND($T11>=$F11,$U11>=$L11),"Увеличить вес",IF($U11>=$L11+2,"Увеличить вес (RIR слишком высокий — вес занижен)",IF($U11<$L11,"Оставить вес; останавливайся раньше (RIR ниже цели)","Оставить вес, добирай повторения")))))) -> Нет данных: начни со стартового веса | W11: =IF($R11="",$H11,IF(LEFT($V11,9)="Увеличить",$S11+$N11,IF(LEFT($V11,9)="Уменьшить",MAX(0,$S11-$N11),$S11))) -> 10
